# Error of checking the latest version of pip

If you run the this command:

```
pip3 install -r requirements-dev.txt
```

And meet the following error:

```
ERROR: Exception:
Traceback (most recent call last):
  File "/Users/username/.pyenv/versions/3.10.16/lib/python3.10/site-packages/pip/_internal/cli/base_command.py", line 160, in exc_logging_wrapper
    status = run_func(*args)
  File "/Users/username/.pyenv/versions/3.10.16/lib/python3.10/site-packages/pip/_internal/cli/req_command.py", line 247, in wrapper
    return func(self, options, args)
  File "/Users/username/.pyenv/versions/3.10.16/lib/python3.10/site-packages/pip/_internal/commands/install.py", line 419, in run
    requirement_set = resolver.resolve(
  File "/Users/username/.pyenv/versions/3.10.16/lib/python3.10/site-packages/pip/_internal/resolution/resolvelib/resolver.py", line 92, in resolve
    result = self._result = resolver.resolve(
  File "/Users/username/.pyenv/versions/3.10.16/lib/python3.10/site-packages/pip/_vendor/resolvelib/resolvers.py", line 481, in resolve
    state = resolution.resolve(requirements, max_rounds=max_rounds)
  File "/Users/username/.pyenv/versions/3.10.16/lib/python3.10/site-packages/pip/_vendor/resolvelib/resolvers.py", line 348, in resolve
    self._add_to_criteria(self.state.criteria, r, parent=None)
  File "/Users/username/.pyenv/versions/3.10.16/lib/python3.10/site-packages/pip/_vendor/resolvelib/resolvers.py", line 172, in _add_to_criteria
    if not criterion.candidates:
  File "/Users/username/.pyenv/versions/3.10.16/lib/python3.10/site-packages/pip/_vendor/resolvelib/structs.py", line 151, in __bool__
    return bool(self._sequence)
  File "/Users/username/.pyenv/versions/3.10.16/lib/python3.10/site-packages/pip/_internal/resolution/resolvelib/found_candidates.py", line 155, in __bool__
    return any(self)
  File "/Users/username/.pyenv/versions/3.10.16/lib/python3.10/site-packages/pip/_internal/resolution/resolvelib/found_candidates.py", line 143, in <genexpr>
    return (c for c in iterator if id(c) not in self._incompatible_ids)
  File "/Users/username/.pyenv/versions/3.10.16/lib/python3.10/site-packages/pip/_internal/resolution/resolvelib/found_candidates.py", line 44, in _iter_built
    for version, func in infos:
  File "/Users/username/.pyenv/versions/3.10.16/lib/python3.10/site-packages/pip/_internal/resolution/resolvelib/factory.py", line 279, in iter_index_candidate_infos
    result = self._finder.find_best_candidate(
  File "/Users/username/.pyenv/versions/3.10.16/lib/python3.10/site-packages/pip/_internal/index/package_finder.py", line 890, in find_best_candidate
    candidates = self.find_all_candidates(project_name)
  File "/Users/username/.pyenv/versions/3.10.16/lib/python3.10/site-packages/pip/_internal/index/package_finder.py", line 831, in find_all_candidates
    page_candidates = list(page_candidates_it)
  File "/Users/username/.pyenv/versions/3.10.16/lib/python3.10/site-packages/pip/_internal/index/sources.py", line 134, in page_candidates
    yield from self._candidates_from_page(self._link)
  File "/Users/username/.pyenv/versions/3.10.16/lib/python3.10/site-packages/pip/_internal/index/package_finder.py", line 791, in process_project_url
    index_response = self._link_collector.fetch_response(project_url)
  File "/Users/username/.pyenv/versions/3.10.16/lib/python3.10/site-packages/pip/_internal/index/collector.py", line 461, in fetch_response
    return _get_index_content(location, session=self.session)
  File "/Users/username/.pyenv/versions/3.10.16/lib/python3.10/site-packages/pip/_internal/index/collector.py", line 364, in _get_index_content
    resp = _get_simple_response(url, session=session)
  File "/Users/username/.pyenv/versions/3.10.16/lib/python3.10/site-packages/pip/_internal/index/collector.py", line 135, in _get_simple_response
    resp = session.get(
  File "/Users/username/.pyenv/versions/3.10.16/lib/python3.10/site-packages/pip/_vendor/requests/sessions.py", line 600, in get
    return self.request("GET", url, **kwargs)
  File "/Users/username/.pyenv/versions/3.10.16/lib/python3.10/site-packages/pip/_internal/network/session.py", line 518, in request
    return super().request(method, url, *args, **kwargs)
  File "/Users/username/.pyenv/versions/3.10.16/lib/python3.10/site-packages/pip/_vendor/requests/sessions.py", line 587, in request
    resp = self.send(prep, **send_kwargs)
  File "/Users/username/.pyenv/versions/3.10.16/lib/python3.10/site-packages/pip/_vendor/requests/sessions.py", line 701, in send
    r = adapter.send(request, **kwargs)
  File "/Users/username/.pyenv/versions/3.10.16/lib/python3.10/site-packages/pip/_vendor/cachecontrol/adapter.py", line 57, in send
    resp = super(CacheControlAdapter, self).send(request, **kw)
  File "/Users/username/.pyenv/versions/3.10.16/lib/python3.10/site-packages/pip/_vendor/requests/adapters.py", line 489, in send
    resp = conn.urlopen(
  File "/Users/username/.pyenv/versions/3.10.16/lib/python3.10/site-packages/pip/_vendor/urllib3/connectionpool.py", line 703, in urlopen
    httplib_response = self._make_request(
  File "/Users/username/.pyenv/versions/3.10.16/lib/python3.10/site-packages/pip/_vendor/urllib3/connectionpool.py", line 386, in _make_request
    self._validate_conn(conn)
  File "/Users/username/.pyenv/versions/3.10.16/lib/python3.10/site-packages/pip/_vendor/urllib3/connectionpool.py", line 1042, in _validate_conn
    conn.connect()
  File "/Users/username/.pyenv/versions/3.10.16/lib/python3.10/site-packages/pip/_vendor/urllib3/connection.py", line 457, in connect
    if not cert.get("subjectAltName", ()):
AttributeError: 'NoneType' object has no attribute 'get'
WARNING: There was an error checking the latest version of pip.
```

It looks like your `pip` installation is encountering an SSL-related issue while trying to fetch dependencies from PyPI. Here are some steps to troubleshoot and fix it:

### 1. **Ensure `pip` and `setuptools` are up to date**
Try upgrading `pip` and `setuptools` first:
```sh
python3 -m pip install --upgrade pip setuptools
```
Then retry the installation:
```sh
pip3 install -r requirements-dev.txt
```

---

### 2. **Check Your Internet Connection**
- Ensure you have a stable internet connection.
- If youâ€™re behind a proxy, set it correctly:
  ```sh
  export HTTP_PROXY=http://your-proxy:port
  export HTTPS_PROXY=https://your-proxy:port
  ```

---

### 3. **Try Using the `--trusted-host` Flag**
Run the install command with additional flags:
```sh
pip3 install --trusted-host pypi.org --trusted-host pypi.python.org --trusted-host=files.pythonhosted.org -r requirements-dev.txt
```

---

### 4. **Clear `pip` Cache**
Try clearing `pip`'s cache to remove any corrupted files:
```sh
pip3 cache purge
```
Then retry the installation.

---

### 5. **Reinstall `pip`**
If the issue persists, reinstall `pip`:
```sh
python3 -m ensurepip --default-pip
python3 -m pip install --upgrade pip
```

---

### 6. **Use a Different Python Environment**
Try creating a new virtual environment:
```sh
python3 -m venv venv
source venv/bin/activate  # On macOS/Linux
venv\Scripts\activate     # On Windows
pip install -r requirements-dev.txt
```
